<?xml version="1.0" encoding="utf-8"?>
<!-- This URDF was automatically created by SolidWorks to URDF Exporter! Originally created by Stephen Brawner (brawner@gmail.com) 
     Commit Version: 1.6.0-1-g15f4949  Build Version: 1.6.7594.29634
     For more information, please see http://wiki.ros.org/sw_urdf_exporter -->
<robot
  name="full2">
  <link
    name="base_link">
    <inertial>
      <origin
        xyz="0 -0.0075 2.79615380305955E-19"
        rpy="0 0 0" />
      <mass
        value="0.0628725" />
      <inertia
        ixx="1.454057546875E-05"
        ixy="1.55096364853693E-22"
        ixz="2.45683431010415E-21"
        iyy="4.945577046875E-05"
        iyz="3.01778780865393E-23"
        izz="3.727291375E-05" />
    </inertial>
    <visual>
      <origin
        xyz="0 0 0"
        rpy="0 0 0" />
      <geometry>
        <mesh
          filename="C:\Users\sq\Documents\full2\meshes\base_link.STL" />
      </geometry>
      <material
        name="">
        <color
          rgba="0.627450980392157 0.627450980392157 0.627450980392157 1" />
      </material>
    </visual>
    <collision>
      <origin
        xyz="0 0 0"
        rpy="0 0 0" />
      <geometry>
        <mesh
          filename="C:\Users\sq\Documents\full2\meshes\base_link.STL" />
      </geometry>
    </collision>
  </link>
  <link
    name="a">
    <inertial>
      <origin
        xyz="0.0971605555469476 -0.000655813706978328 0.210000000000003"
        rpy="0 0 0" />
      <mass
        value="0.049612609423567" />
      <inertia
        ixx="0.000178154813120551"
        ixy="-5.09732787104479E-22"
        ixz="2.48111929115812E-11"
        iyy="0.00026408667344509"
        iyz="2.97869951361546E-20"
        izz="8.59649354000058E-05" />
    </inertial>
    <visual>
      <origin
        xyz="0 0 0"
        rpy="0 0 0" />
      <geometry>
        <mesh
          filename="C:\Users\sq\Documents\full2\meshes\a.STL" />
      </geometry>
      <material
        name="">
        <color
          rgba="0.0980392156862745 0.0980392156862745 0.0980392156862745 1" />
      </material>
    </visual>
    <collision>
      <origin
        xyz="0 0 0"
        rpy="0 0 0" />
      <geometry>
        <mesh
          filename="C:\Users\sq\Documents\full2\meshes\a.STL" />
      </geometry>
    </collision>
  </link>
  <joint
    name="a"
    type="fixed">
    <origin
      xyz="-0.21 0.097160555546947 -0.016655813706978"
      rpy="-1.5707963267949 0 -1.5707963267949" />
    <parent
      link="base_link" />
    <child
      link="a" />
    <axis
      xyz="0 0 0" />
  </joint>
  <link
    name="b">
    <inertial>
      <origin
        xyz="-0.000999999999999959 0.0116670262507582 -0.17499997935196"
        rpy="0 0 0" />
      <mass
        value="0.0946817219162806" />
      <inertia
        ixx="0.00129606828747054"
        ixy="-3.5656698947617E-16"
        ixz="1.45335469481914E-18"
        iyy="0.00117142838007768"
        iyz="1.73286367180895E-09"
        izz="0.000124703028808836" />
    </inertial>
    <visual>
      <origin
        xyz="0 0 0"
        rpy="0 0 0" />
      <geometry>
        <mesh
          filename="C:\Users\sq\Documents\full2\meshes\b.STL" />
      </geometry>
      <material
        name="">
        <color
          rgba="0.0980392156862745 0.0980392156862745 0.0980392156862745 1" />
      </material>
    </visual>
    <collision>
      <origin
        xyz="0 0 0"
        rpy="0 0 0" />
      <geometry>
        <mesh
          filename="C:\Users\sq\Documents\full2\meshes\b.STL" />
      </geometry>
    </collision>
  </link>
  <joint
    name="b"
    type="fixed">
    <origin
      xyz="0.175 -0.097178593586223 -0.017010467191248"
      rpy="1.5707963267949 0.0523598775598271 1.5707963267949" />
    <parent
      link="base_link" />
    <child
      link="b" />
    <axis
      xyz="0 0 0" />
  </joint>
  <link
    name="c">
    <inertial>
      <origin
        xyz="-0.000999999999999987 0.0116670262507573 -0.17499997935196"
        rpy="0 0 0" />
      <mass
        value="0.0946817219162811" />
      <inertia
        ixx="0.00129606828747055"
        ixy="-3.56384030359563E-16"
        ixz="1.57147144632547E-18"
        iyy="0.00117142838007768"
        iyz="1.73286366971367E-09"
        izz="0.000124703028808837" />
    </inertial>
    <visual>
      <origin
        xyz="0 0 0"
        rpy="0 0 0" />
      <geometry>
        <mesh
          filename="C:\Users\sq\Documents\full2\meshes\c.STL" />
      </geometry>
      <material
        name="">
        <color
          rgba="0.0980392156862745 0.0980392156862745 0.0980392156862745 1" />
      </material>
    </visual>
    <collision>
      <origin
        xyz="0 0 0"
        rpy="0 0 0" />
      <geometry>
        <mesh
          filename="C:\Users\sq\Documents\full2\meshes\c.STL" />
      </geometry>
    </collision>
  </link>
  <joint
    name="c"
    type="fixed">
    <origin
      xyz="-0.175 0.097178593586224 -0.017"
      rpy="1.5707963267949 0.052359877559827 -1.5707963267949" />
    <parent
      link="base_link" />
    <child
      link="c" />
    <axis
      xyz="0 0 0" />
  </joint>
  <link
    name="d">
    <inertial>
      <origin
        xyz="2.84762890186922E-07 0.050212968460409 0.0805514822346239"
        rpy="0 0 0" />
      <mass
        value="0.0514644320422948" />
      <inertia
        ixx="0.000177634625069099"
        ixy="4.49675621513154E-10"
        ixz="-2.66385744785241E-10"
        iyy="0.000245810252117827"
        iyz="-2.7282069300441E-05"
        izz="0.000302714730467749" />
    </inertial>
    <visual>
      <origin
        xyz="0 0 0"
        rpy="0 0 0" />
      <geometry>
        <mesh
          filename="C:\Users\sq\Documents\full2\meshes\d.STL" />
      </geometry>
      <material
        name="">
        <color
          rgba="0.96078431372549 0.96078431372549 0.964705882352941 1" />
      </material>
    </visual>
    <collision>
      <origin
        xyz="0 0 0"
        rpy="0 0 0" />
      <geometry>
        <mesh
          filename="C:\Users\sq\Documents\full2\meshes\d.STL" />
      </geometry>
    </collision>
  </link>
  <joint
    name="d"
    type="fixed">
    <origin
      xyz="0.09 -9.98629534750042E-05 -0.068930142767599"
      rpy="1.5707963267949 0 1.5707963267949" />
    <parent
      link="base_link" />
    <child
      link="d" />
    <axis
      xyz="0 0 0" />
  </joint>
  <link
    name="e">
    <inertial>
      <origin
        xyz="2.8476290749133E-07 -0.0502129684604379 -0.0805514822346179"
        rpy="0 0 0" />
      <mass
        value="0.0514644320423025" />
      <inertia
        ixx="0.00017763462506918"
        ixy="-4.49675544823781E-10"
        ixz="2.66385752620918E-10"
        iyy="0.000245810252117834"
        iyz="-2.72820693004333E-05"
        izz="0.000302714730467861" />
    </inertial>
    <visual>
      <origin
        xyz="0 0 0"
        rpy="0 0 0" />
      <geometry>
        <mesh
          filename="C:\Users\sq\Documents\full2\meshes\e.STL" />
      </geometry>
      <material
        name="">
        <color
          rgba="0.96078431372549 0.96078431372549 0.964705882352941 1" />
      </material>
    </visual>
    <collision>
      <origin
        xyz="0 0 0"
        rpy="0 0 0" />
      <geometry>
        <mesh
          filename="C:\Users\sq\Documents\full2\meshes\e.STL" />
      </geometry>
    </collision>
  </link>
  <joint
    name="e"
    type="fixed">
    <origin
      xyz="-0.09 9.98629534759958E-05 -0.068919675576351"
      rpy="-1.5707963267949 0 -1.5707963267949" />
    <parent
      link="base_link" />
    <child
      link="e" />
    <axis
      xyz="0 0 0" />
  </joint>
  <link
    name="f">
    <inertial>
      <origin
        xyz="0.023553802391134 -5.6360682076928E-07 -5.1173074583355E-08"
        rpy="0 0 0" />
      <mass
        value="0.00607742634204188" />
      <inertia
        ixx="5.24166473218621E-07"
        ixy="-3.03611004714958E-10"
        ixz="4.00627348583702E-10"
        iyy="2.7473361125745E-06"
        iyz="1.54952377986803E-10"
        izz="2.74696945906015E-06" />
    </inertial>
    <visual>
      <origin
        xyz="0 0 0"
        rpy="0 0 0" />
      <geometry>
        <mesh
          filename="C:\Users\sq\Documents\full2\meshes\f.STL" />
      </geometry>
      <material
        name="">
        <color
          rgba="0.96078431372549 0.96078431372549 0.964705882352941 1" />
      </material>
    </visual>
    <collision>
      <origin
        xyz="0 0 0"
        rpy="0 0 0" />
      <geometry>
        <mesh
          filename="C:\Users\sq\Documents\full2\meshes\f.STL" />
      </geometry>
    </collision>
  </link>
  <joint
    name="f"
    type="fixed">
    <origin
      xyz="0.175 -0.107164888933769 -0.016487107628819"
      rpy="2.35619449019235 0.0523598775598078 1.57079632679492" />
    <parent
      link="base_link" />
    <child
      link="f" />
    <axis
      xyz="0 0 0" />
  </joint>
  <link
    name="hip12">
    <inertial>
      <origin
        xyz="0.00476247007204403 -0.03505339115663 5.30398006702015E-05"
        rpy="0 0 0" />
      <mass
        value="0.00927126538729555" />
      <inertia
        ixx="1.18961540675349E-05"
        ixy="6.82662752221537E-12"
        ixz="3.83294560278405E-12"
        iyy="7.00282692744997E-07"
        iyz="-1.72578501877626E-08"
        izz="1.13371843068628E-05" />
    </inertial>
    <visual>
      <origin
        xyz="0 0 0"
        rpy="0 0 0" />
      <geometry>
        <mesh
          filename="C:\Users\sq\Documents\full2\meshes\hip12.STL" />
      </geometry>
      <material
        name="">
        <color
          rgba="0.96078431372549 0.96078431372549 0.964705882352941 1" />
      </material>
    </visual>
    <collision>
      <origin
        xyz="0 0 0"
        rpy="0 0 0" />
      <geometry>
        <mesh
          filename="C:\Users\sq\Documents\full2\meshes\hip12.STL" />
      </geometry>
    </collision>
  </link>
  <joint
    name="hip12"
    type="continuous">
    <origin
      xyz="-0.012525 0 0"
      rpy="0 0 0" />
    <parent
      link="f" />
    <child
      link="hip12" />
    <axis
      xyz="-1 0 0" />
  </joint>
  <link
    name="knee12">
    <inertial>
      <origin
        xyz="1.11022302462516E-16 -0.0778812653760311 -2.91433543964104E-16"
        rpy="0 0 0" />
      <mass
        value="0.0251043154563417" />
      <inertia
        ixx="8.49264078812272E-05"
        ixy="-5.11836718978545E-19"
        ixz="-1.46113183401367E-20"
        iyy="1.15952270341936E-06"
        iyz="-6.83648232662826E-20"
        izz="8.5706329799651E-05" />
    </inertial>
    <visual>
      <origin
        xyz="0 0 0"
        rpy="0 0 0" />
      <geometry>
        <mesh
          filename="C:\Users\sq\Documents\full2\meshes\knee12.STL" />
      </geometry>
      <material
        name="">
        <color
          rgba="0.898039215686275 0.917647058823529 0.929411764705882 1" />
      </material>
    </visual>
    <collision>
      <origin
        xyz="0 0 0"
        rpy="0 0 0" />
      <geometry>
        <mesh
          filename="C:\Users\sq\Documents\full2\meshes\knee12.STL" />
      </geometry>
    </collision>
  </link>
  <joint
    name="knee12"
    type="continuous">
    <origin
      xyz="0.24691 -0.19066 -0.18039"
      rpy="-1.4282 -1.0136 1.5258" />
    <parent
      link="hip12" />
    <child
      link="knee12" />
    <axis
      xyz="-0.008056 -0.015332 -0.99985" />
  </joint>
  <link
    name="g">
    <inertial>
      <origin
        xyz="0.0346629785770797 -4.25560339537001E-07 -4.70560418408539E-09"
        rpy="0 0 0" />
      <mass
        value="0.011007632070168" />
      <inertia
        ixx="1.99004578144606E-07"
        ixy="2.51663009439391E-12"
        ixz="7.20469235917211E-11"
        iyy="8.83795085267254E-06"
        iyz="5.20865088904815E-12"
        izz="8.8362422388697E-06" />
    </inertial>
    <visual>
      <origin
        xyz="0 0 0"
        rpy="0 0 0" />
      <geometry>
        <mesh
          filename="C:\Users\sq\Documents\full2\meshes\g.STL" />
      </geometry>
      <material
        name="">
        <color
          rgba="0.96078431372549 0.96078431372549 0.964705882352941 1" />
      </material>
    </visual>
    <collision>
      <origin
        xyz="0 0 0"
        rpy="0 0 0" />
      <geometry>
        <mesh
          filename="C:\Users\sq\Documents\full2\meshes\g.STL" />
      </geometry>
    </collision>
  </link>
  <joint
    name="g"
    type="fixed">
    <origin
      xyz="0.175 -0.11615255474656 -0.016016084022632"
      rpy="2.35619449019235 0.0523598775598309 1.5707963267949" />
    <parent
      link="base_link" />
    <child
      link="g" />
    <axis
      xyz="0 0 0" />
  </joint>
  <link
    name="hip11">
    <inertial>
      <origin
        xyz="0.00476249715064442 -0.0400529157129809 -0.000402825970655468"
        rpy="0 0 0" />
      <mass
        value="0.00662276690952864" />
      <inertia
        ixx="8.45744188288639E-06"
        ixy="4.6661776742085E-13"
        ixz="-7.65669893339748E-14"
        iyy="3.06836587423927E-07"
        iyz="1.06071227697578E-07"
        izz="8.25196880727023E-06" />
    </inertial>
    <visual>
      <origin
        xyz="0 0 0"
        rpy="0 0 0" />
      <geometry>
        <mesh
          filename="C:\Users\sq\Documents\full2\meshes\hip11.STL" />
      </geometry>
      <material
        name="">
        <color
          rgba="0.96078431372549 0.96078431372549 0.964705882352941 1" />
      </material>
    </visual>
    <collision>
      <origin
        xyz="0 0 0"
        rpy="0 0 0" />
      <geometry>
        <mesh
          filename="C:\Users\sq\Documents\full2\meshes\hip11.STL" />
      </geometry>
    </collision>
  </link>
  <joint
    name="hip11"
    type="continuous">
    <origin
      xyz="-0.01405 0 0"
      rpy="-2.1263 0 0" />
    <parent
      link="g" />
    <child
      link="hip11" />
    <axis
      xyz="-1 0 0" />
  </joint>
  <link
    name="knee11">
    <inertial>
      <origin
        xyz="-2.69784194983913E-14 -0.0857929956840996 -2.49999999943351E-06"
        rpy="0 0 0" />
      <mass
        value="0.0304320456503239" />
      <inertia
        ixx="0.000123727676354291"
        ixy="6.73135883771104E-17"
        ixz="3.04931861011548E-20"
        iyy="1.02351723365095E-06"
        iyz="1.40131013211383E-19"
        izz="0.000124291032527665" />
    </inertial>
    <visual>
      <origin
        xyz="0 0 0"
        rpy="0 0 0" />
      <geometry>
        <mesh
          filename="C:\Users\sq\Documents\full2\meshes\knee11.STL" />
      </geometry>
      <material
        name="">
        <color
          rgba="0.898039215686275 0.917647058823529 0.929411764705882 1" />
      </material>
    </visual>
    <collision>
      <origin
        xyz="0 0 0"
        rpy="0 0 0" />
      <geometry>
        <mesh
          filename="C:\Users\sq\Documents\full2\meshes\knee11.STL" />
      </geometry>
    </collision>
  </link>
  <joint
    name="knee11"
    type="continuous">
    <origin
      xyz="0.25029 0.39099 -0.1443"
      rpy="1.7779 -1.008 -1.7101" />
    <parent
      link="hip11" />
    <child
      link="knee11" />
    <axis
      xyz="-0.001857 0.013655 0.99991" />
  </joint>
</robot>